2017-04-11 09:27:17.365 - eddnlistener - WARNING - eddnlistener.main: Disconnect from tcp://eddn-relay.elite-markets.net:9500
Traceback (most recent call last):
  File "./eddnlistener.py", line 92, in main
    __message   = __subscriber.recv()
  File "zmq/backend/cython/socket.pyx", line 631, in zmq.backend.cython.socket.Socket.recv (zmq/backend/cython/socket.c:5772)
  File "zmq/backend/cython/socket.pyx", line 665, in zmq.backend.cython.socket.Socket.recv (zmq/backend/cython/socket.c:5572)
  File "zmq/backend/cython/socket.pyx", line 139, in zmq.backend.cython.socket._recv_copy (zmq/backend/cython/socket.c:1725)
  File "zmq/backend/cython/checkrc.pxd", line 15, in zmq.backend.cython.checkrc._check_rc (zmq/backend/cython/socket.c:6112)
zmq.error.Again: Resource temporarily unavailable

During handling of the above exception, another exception occurred:

Traceback (most recent call last):
  File "./eddnlistener.py", line 202, in <module>
    main()
  File "./eddnlistener.py", line 135, in main
    time.sleep(5)
NameError: name 'time' is not defined
You have mail in /home/users/athan/Maildir
athan@tuesday:/mnt/tuesday/data0/edda/edda.git/eddn-listener;
10:27:17 0$

-=-=-=-=-=-=-=-=-=-=-=-=-=-=-=-=-=-=-=-=-=-=-=-=-=-=-=-=-=-=-=-=-=-=-=-=-=
Wed 10 May 12:59:36 BST 2017
2017-05-07 02:10:38.953 - eddnlistener - INFO - utils.validateEDDNMessage: Blacklisted ED-IBE (API) (0.6.4)
Traceback (most recent call last):
  File "/usr/lib/python3/dist-packages/sqlalchemy/engine/base.py", line 951, in _execute_context
    context)
  File "/usr/lib/python3/dist-packages/sqlalchemy/engine/default.py", line 436, in do_execute
    cursor.execute(statement, parameters)
psycopg2.OperationalError: terminating connection due to administrator command
SSL connection has been closed unexpectedly


The above exception was the direct cause of the following exception:

Traceback (most recent call last):
  File "./eddnlistener.py", line 174, in <module>
    main()
  File "./eddnlistener.py", line 142, in main
    __db.insertMessage(__eddn_message.json, __message_blacklisted, __message_valid, __message_schema_is_test)
  File "/mnt/tuesday/data0/edda/edda.git/eddn-listener/eddn/database/database.py", line 29, in insertMessage
    session.commit()
  File "/usr/lib/python3/dist-packages/sqlalchemy/orm/session.py", line 776, in commit
    self.transaction.commit()
  File "/usr/lib/python3/dist-packages/sqlalchemy/orm/session.py", line 377, in commit
    self._prepare_impl()
  File "/usr/lib/python3/dist-packages/sqlalchemy/orm/session.py", line 357, in _prepare_impl
    self.session.flush()
  File "/usr/lib/python3/dist-packages/sqlalchemy/orm/session.py", line 1919, in flush
    self._flush(objects)
  File "/usr/lib/python3/dist-packages/sqlalchemy/orm/session.py", line 2037, in _flush
    transaction.rollback(_capture_exception=True)
  File "/usr/lib/python3/dist-packages/sqlalchemy/util/langhelpers.py", line 60, in __exit__
    compat.reraise(exc_type, exc_value, exc_tb)
  File "/usr/lib/python3/dist-packages/sqlalchemy/util/compat.py", line 182, in reraise
    raise value
  File "/usr/lib/python3/dist-packages/sqlalchemy/orm/session.py", line 2001, in _flush
    flush_context.execute()
  File "/usr/lib/python3/dist-packages/sqlalchemy/orm/unitofwork.py", line 372, in execute
    rec.execute(self)
  File "/usr/lib/python3/dist-packages/sqlalchemy/orm/unitofwork.py", line 526, in execute
    uow
  File "/usr/lib/python3/dist-packages/sqlalchemy/orm/persistence.py", line 65, in save_obj
    mapper, table, insert)
  File "/usr/lib/python3/dist-packages/sqlalchemy/orm/persistence.py", line 602, in _emit_insert_statements
    execute(statement, params)
  File "/usr/lib/python3/dist-packages/sqlalchemy/engine/base.py", line 729, in execute
    return meth(self, multiparams, params)
  File "/usr/lib/python3/dist-packages/sqlalchemy/sql/elements.py", line 322, in _execute_on_connection
    return connection._execute_clauseelement(self, multiparams, params)
  File "/usr/lib/python3/dist-packages/sqlalchemy/engine/base.py", line 826, in _execute_clauseelement
    compiled_sql, distilled_params
  File "/usr/lib/python3/dist-packages/sqlalchemy/engine/base.py", line 958, in _execute_context
    context)
  File "/usr/lib/python3/dist-packages/sqlalchemy/engine/base.py", line 1159, in _handle_dbapi_exception
    exc_info
  File "/usr/lib/python3/dist-packages/sqlalchemy/util/compat.py", line 188, in raise_from_cause
    reraise(type(exception), exception, tb=exc_tb, cause=exc_value)
  File "/usr/lib/python3/dist-packages/sqlalchemy/util/compat.py", line 181, in reraise
    raise value.with_traceback(tb)
  File "/usr/lib/python3/dist-packages/sqlalchemy/engine/base.py", line 951, in _execute_context
    context)
  File "/usr/lib/python3/dist-packages/sqlalchemy/engine/default.py", line 436, in do_execute
    cursor.execute(statement, parameters)
sqlalchemy.exc.OperationalError: (OperationalError) terminating connection due to administrator command
SSL connection has been closed unexpectedly
 'INSERT INTO messages (message_raw, message, blacklisted, message_valid, schema_test) VALUES (%(message_raw)s, %(message)s, %(blacklisted)s, %(message_valid)s, %(schema_test)s) RETURNING messages.id' {'message_raw': '{"$schemaRef": "http://schemas.elite-markets.net/eddn/journal/1", "header": {"softwareVersion": "7.0.0.0", "uploaderID": "Felina Hawk", "gatewayTimestamp": "2017-05-07T02:11:39.990741Z", "softwareName": "EDDiscovery"}, "message": {"timestamp": "2017-05-07T02:11:39Z", "Age_MY": 3102, "StarType": "N", "RotationPeriod": 1.844558, "StarPos": [-14434.125, -10.0, 29932.75], "event": "Scan", "SurfaceTemperature": 5471000.0, "StellarMass": 0.742188, "StarSystem": "Eowyg Brai YS-U d2-70", "Radius": 11082.03125, "BodyName": "Eowyg Brai YS-U d2-70", "AbsoluteMagnitude": 5.134415, "DistanceFromArrivalLS": 0.0}}', 'message_valid': True, 'message': '{"$schemaRef": "http://schemas.elite-markets.net/eddn/journal/1", "header": {"softwareVersion": "7.0.0.0", "uploaderID": "Felina Hawk", "gatewayTimestamp": "2017-05-07T02:11:39.990741Z", "softwareName": "EDDiscovery"}, "message": {"timestamp": "2017-05-07T02:11:39Z", "Age_MY": 3102, "StarType": "N", "RotationPeriod": 1.844558, "StarPos": [-14434.125, -10.0, 29932.75], "event": "Scan", "SurfaceTemperature": 5471000.0, "StellarMass": 0.742188, "StarSystem": "Eowyg Brai YS-U d2-70", "Radius": 11082.03125, "BodyName": "Eowyg Brai YS-U d2-70", "AbsoluteMagnitude": 5.134415, "DistanceFromArrivalLS": 0.0}}', 'schema_test': False, 'blacklisted': False}
You have mail in /home/users/athan/Maildir
athan@tuesday:/mnt/tuesday/data0/edda/edda.git/eddn-listener;
03:11:45 1$
-=-=-=-=-=-=-=-=-=-=-=-=-=-=-=-=-=-=-=-=-=-=-=-=-=-=-=-=-=-=-=-=-=-=-=-=-=
Startup is very slow when looking to backfill EDDN messages and trying
to find the latest message of a given type, i.e.:

2017-05-10 13:17:56 BST [26980-2] eddnlistener@eddn STATEMENT:  SELECT messages.message AS messages_message 
        FROM messages 
        WHERE (messages.message ->> '$schemaRef') LIKE '%blackmarket%' AND (messages.message #> '{header, gatewayTimestamp}') IS NOT NULL ORDER BY messages.message #> '{header, gatewayTimestamp}' DESC 
         LIMIT 1

is very slow.  It comes from this in eddn/database/database.py:

  def latestMessageTimestamp(self, archiveType):
    session = self.Session()
    gatewayTimestamp = Message.message[("header", "gatewayTimestamp")]
    schema = Message.message[("$schemaRef")].astext
    results = session.query(Message.message).filter(schema.like("%"+archiveType+"%")).filter(gatewayTimestamp != None).order_by(desc(gatewayTimestamp)).limit(1)
    for r in results:
      return r.message['header']['gatewayTimestamp']
-=-=-=-=-=-=-=-=-=-=-=-=-=-=-=-=-=-=-=-=-=-=-=-=-=-=-=-=-=-=-=-=-=-=-=-=-=
Wed 26 Jul 21:39:38 BST 2017
2017-07-26 19:50:24.986 - eddnlistener - INFO - utils.validateEDDNMessage: Blacklisted EDDiscovery (8.1.3.0)
Traceback (most recent call last):
  File "/usr/lib/python3/dist-packages/sqlalchemy/engine/base.py", line 1139, in _execute_context
    context)
  File "/usr/lib/python3/dist-packages/sqlalchemy/engine/default.py", line 450, in do_execute
    cursor.execute(statement, parameters)
psycopg2.InternalError: invalid page in block 130948 of relation base/16394/16455


The above exception was the direct cause of the following exception:

Traceback (most recent call last):
  File "/mnt/tuesday/data0/edda/edda.git/eddn-listener/eddn/database/database.py", line 35, in insertMessage
    session.commit()
  File "/usr/lib/python3/dist-packages/sqlalchemy/orm/session.py", line 801, in commit
    self.transaction.commit()
  File "/usr/lib/python3/dist-packages/sqlalchemy/orm/session.py", line 392, in commit
    self._prepare_impl()
  File "/usr/lib/python3/dist-packages/sqlalchemy/orm/session.py", line 372, in _prepare_impl
    self.session.flush()
  File "/usr/lib/python3/dist-packages/sqlalchemy/orm/session.py", line 2019, in flush
    self._flush(objects)
  File "/usr/lib/python3/dist-packages/sqlalchemy/orm/session.py", line 2137, in _flush
    transaction.rollback(_capture_exception=True)
  File "/usr/lib/python3/dist-packages/sqlalchemy/util/langhelpers.py", line 60, in __exit__
    compat.reraise(exc_type, exc_value, exc_tb)
  File "/usr/lib/python3/dist-packages/sqlalchemy/util/compat.py", line 186, in reraise
    raise value
  File "/usr/lib/python3/dist-packages/sqlalchemy/orm/session.py", line 2101, in _flush
    flush_context.execute()
  File "/usr/lib/python3/dist-packages/sqlalchemy/orm/unitofwork.py", line 373, in execute
    rec.execute(self)
  File "/usr/lib/python3/dist-packages/sqlalchemy/orm/unitofwork.py", line 532, in execute
    uow
  File "/usr/lib/python3/dist-packages/sqlalchemy/orm/persistence.py", line 174, in save_obj
    mapper, table, insert)
  File "/usr/lib/python3/dist-packages/sqlalchemy/orm/persistence.py", line 800, in _emit_insert_statements
    execute(statement, params)
  File "/usr/lib/python3/dist-packages/sqlalchemy/engine/base.py", line 914, in execute
    return meth(self, multiparams, params)
  File "/usr/lib/python3/dist-packages/sqlalchemy/sql/elements.py", line 323, in _execute_on_connection
    return connection._execute_clauseelement(self, multiparams, params)
  File "/usr/lib/python3/dist-packages/sqlalchemy/engine/base.py", line 1010, in _execute_clauseelement
    compiled_sql, distilled_params
  File "/usr/lib/python3/dist-packages/sqlalchemy/engine/base.py", line 1146, in _execute_context
    context)
  File "/usr/lib/python3/dist-packages/sqlalchemy/engine/base.py", line 1341, in _handle_dbapi_exception
    exc_info
  File "/usr/lib/python3/dist-packages/sqlalchemy/util/compat.py", line 202, in raise_from_cause
    reraise(type(exception), exception, tb=exc_tb, cause=cause)
  File "/usr/lib/python3/dist-packages/sqlalchemy/util/compat.py", line 185, in reraise
    raise value.with_traceback(tb)
  File "/usr/lib/python3/dist-packages/sqlalchemy/engine/base.py", line 1139, in _execute_context
    context)
  File "/usr/lib/python3/dist-packages/sqlalchemy/engine/default.py", line 450, in do_execute
    cursor.execute(statement, parameters)
sqlalchemy.exc.InternalError: (psycopg2.InternalError) invalid page in block 130948 of relation base/16394/16455
 [SQL: 'INSERT INTO messages (message, message_search, blacklisted, message_valid, schema_test, schemaref, gatewaytimestamp) VALUES (%(message)s, %(message_search)s, %(blacklisted)s, %(message_valid)s, %(schema_test)s, %(schemaref)s, %(gatewaytimestamp)s) RETURNING messages.id'] [parameters: {'message': '{"header": {"uploaderID": "BeanGTR", "softwareVersion": "2.3.0", "gatewayTimestamp": "2017-07-26T19:50:15.321473Z", "softwareName": "EDDI"}, "message": {"PlanetClass": "High metal content body", "SemiMajorAxis": 1069009797120.0, "StarPos": [-206.78125, 27.1875, -92.25], "event": "Scan", "timestamp": "2017-07-26T19:50:34Z", "DistanceFromArrivalLS": 3591.29541, "Radius": 7715584.5, "OrbitalPeriod": 526916160.0, "MassEM": 2.283549, "Eccentricity": 0.008741, "Periapsis": 150.545395, "RotationPeriod": 118229.296875, "StarSystem": "Col 285 Sector KS-T d3-68", "AxialTilt": -2.86825, "SurfaceGravity": 15.289104, "OrbitalInclination": -0.011449, "BodyName": "Col 285 Sector KS-T d3-68 A 5"}, "$schemaRef": "http://schemas.elite-markets.net/eddn/journal/1"}', 'schema_test': False, 'schemaref': 'journal', 'blacklisted': False, 'message_search': 'null', 'gatewaytimestamp': '2017-07-26T19:50:15.321473Z', 'message_valid': True}]

During handling of the above exception, another exception occurred:

Traceback (most recent call last):
  File "./eddnlistener.py", line 175, in <module>
    main()
  File "./eddnlistener.py", line 142, in main
    __db.insertMessage(__eddn_message.json, __eddn_message.schemaref, __eddn_message.gatewaytimestamp,__message_blacklisted, __message_valid, __message_schema_is_test)
  File "/mnt/tuesday/data0/edda/edda.git/eddn-listener/eddn/database/database.py", line 37, in insertMessage
    except sqlalchemy.exc.OperationalError as ex:
NameError: name 'sqlalchemy' is not defined
athan@tuesday:/mnt/tuesday/data0/edda/edda.git/eddn-listener;
20:50:33 0$
-=-=-=-=-=-=-=-=-=-=-=-=-=-=-=-=-=-=-=-=-=-=-=-=-=-=-=-=-=-=-=-=-=-=-=-=-=
Wed  9 Aug 12:53:27 BST 2017
2017-08-09 11:52:44.193 - eddnlistener - INFO - utils.validateEDDNMessage: Blacklisted ED-IBE (API) (0.6.6)
2017-08-09 11:52:52.924 - eddnlistener - WARNING - utils.validateEDDNMessage: ('$schemaRef did not match regex: https://eddn.edcd.io/schemas/journal/1',)
Traceback (most recent call last):
  File "./eddnlistener.py", line 175, in <module>
    main()
  File "./eddnlistener.py", line 111, in main
    (__eddn_message, __message_valid, __message_blacklisted, __message_schema_is_test) = validateEDDNMessage(__message, __config, __logger)
  File "/mnt/tuesday/data0/edda/edda.git/eddn-listener/eddn/utils.py", line 28, in validateEDDNMessage
    __message_schema_is_test = __eddn_message.schema_is_test
AttributeError: 'message' object has no attribute 'schema_is_test'

FIXED: __eddn_message.schema_is_test was only being initialised AFTER
the "known schema" regex test, which was against the old URLs.  Moved
the initialisation to False earlier as well as updating the schema URL
regex.
-=-=-=-=-=-=-=-=-=-=-=-=-=-=-=-=-=-=-=-=-=-=-=-=-=-=-=-=-=-=-=-=-=-=-=-=-=
Thu 10 Aug 18:35:38 BST 2017
2017-08-10 17:29:10.862 - eddnlistener - INFO - utils.validateEDDNMessage: Blacklisted EDDiscovery (8.1.4.0)
Traceback (most recent call last):
  File "./eddnlistener.py", line 175, in <module>
    main()
  File "./eddnlistener.py", line 111, in main
    (__eddn_message, __message_valid, __message_blacklisted, __message_schema_is_test) = validateEDDNMessage(__message, __config, __logger)
  File "/mnt/tuesday/data0/edda/edda.git/eddn-listener/eddn/utils.py", line 19, in validateEDDNMessage
    __eddn_message.validate()
  File "/mnt/tuesday/data0/edda/edda.git/eddn-listener/eddn/message/message.py", line 84, in validate
    validate(self.json, schemainfo["schema"])
  File "/usr/lib/python3/dist-packages/jsonschema/validators.py", line 478, in validate
    cls(schema, *args, **kwargs).validate(instance)
  File "/usr/lib/python3/dist-packages/jsonschema/validators.py", line 123, in validate
    raise error
jsonschema.exceptions.ValidationError: 'Location' is not one of ['Docked', 'FSDJump', 'Scan']

Failed validating 'enum' in schema['properties']['message']['properties']['event']:
    {'enum': ['Docked', 'FSDJump', 'Scan']}

On instance['message']['event']:
    'Location'
-=-=-=-=-=-=-=-=-=-=-=-=-=-=-=-=-=-=-=-=-=-=-=-=-=-=-=-=-=-=-=-=-=-=-=-=-=
Fri 11 Aug 08:12:29 BST 2017
Due to psql upgrade:
2017-08-10 17:56:48.180 - eddnlistener - INFO - utils.validateEDDNMessage: Blacklisted EDDiscovery (8.1.4.0)
Traceback (most recent call last):
  File "/usr/lib/python3/dist-packages/sqlalchemy/engine/base.py", line 1139, in _execute_context
    context)
  File "/usr/lib/python3/dist-packages/sqlalchemy/engine/default.py", line 450, in do_execute
    cursor.execute(statement, parameters)
psycopg2.OperationalError: terminating connection due to administrator command
server closed the connection unexpectedly
        This probably means the server terminated abnormally
        before or while processing the request.


The above exception was the direct cause of the following exception:

Traceback (most recent call last):
  File "/mnt/tuesday/data0/edda/edda.git/eddn-listener/eddn/database/database.py", line 35, in insertMessage
    session.commit()
  File "/usr/lib/python3/dist-packages/sqlalchemy/orm/session.py", line 801, in commit
    self.transaction.commit()
  File "/usr/lib/python3/dist-packages/sqlalchemy/orm/session.py", line 392, in commit
    self._prepare_impl()
  File "/usr/lib/python3/dist-packages/sqlalchemy/orm/session.py", line 372, in _prepare_impl
    self.session.flush()
  File "/usr/lib/python3/dist-packages/sqlalchemy/orm/session.py", line 2019, in flush
    self._flush(objects)
  File "/usr/lib/python3/dist-packages/sqlalchemy/orm/session.py", line 2137, in _flush
    transaction.rollback(_capture_exception=True)
  File "/usr/lib/python3/dist-packages/sqlalchemy/util/langhelpers.py", line 60, in __exit__
    compat.reraise(exc_type, exc_value, exc_tb)
  File "/usr/lib/python3/dist-packages/sqlalchemy/util/compat.py", line 186, in reraise
    raise value
  File "/usr/lib/python3/dist-packages/sqlalchemy/orm/session.py", line 2101, in _flush
    flush_context.execute()
  File "/usr/lib/python3/dist-packages/sqlalchemy/orm/unitofwork.py", line 373, in execute
    rec.execute(self)
  File "/usr/lib/python3/dist-packages/sqlalchemy/orm/unitofwork.py", line 532, in execute
    uow
  File "/usr/lib/python3/dist-packages/sqlalchemy/orm/persistence.py", line 174, in save_obj
    mapper, table, insert)
  File "/usr/lib/python3/dist-packages/sqlalchemy/orm/persistence.py", line 800, in _emit_insert_statements
    execute(statement, params)
  File "/usr/lib/python3/dist-packages/sqlalchemy/engine/base.py", line 914, in execute
    return meth(self, multiparams, params)
  File "/usr/lib/python3/dist-packages/sqlalchemy/sql/elements.py", line 323, in _execute_on_connection
    return connection._execute_clauseelement(self, multiparams, params)
  File "/usr/lib/python3/dist-packages/sqlalchemy/engine/base.py", line 1010, in _execute_clauseelement
    compiled_sql, distilled_params
  File "/usr/lib/python3/dist-packages/sqlalchemy/engine/base.py", line 1146, in _execute_context
    context)
  File "/usr/lib/python3/dist-packages/sqlalchemy/engine/base.py", line 1341, in _handle_dbapi_exception
    exc_info
  File "/usr/lib/python3/dist-packages/sqlalchemy/util/compat.py", line 202, in raise_from_cause
    reraise(type(exception), exception, tb=exc_tb, cause=cause)
  File "/usr/lib/python3/dist-packages/sqlalchemy/util/compat.py", line 185, in reraise
    raise value.with_traceback(tb)
  File "/usr/lib/python3/dist-packages/sqlalchemy/engine/base.py", line 1139, in _execute_context
    context)
  File "/usr/lib/python3/dist-packages/sqlalchemy/engine/default.py", line 450, in do_execute
    cursor.execute(statement, parameters)
sqlalchemy.exc.OperationalError: (psycopg2.OperationalError) terminating connection due to administrator command
server closed the connection unexpectedly
        This probably means the server terminated abnormally
        before or while processing the request.
 [SQL: 'INSERT INTO messages (message, message_search, blacklisted, message_valid, schema_test, schemaref, gatewaytimestamp) VALUES (%(message)s, %(message_search)s, %(blacklisted)s, %(message_valid)s, %(schema_test)s, %(schemaref)s, %(gatewaytimestamp)s) RETURNING messages.id'] [parameters: {'message_valid': True, 'blacklisted': False, 'message': '{"$schemaRef": "https://eddn.edcd.io/schemas/journal/1", "header": {"softwareName": "E:D Market Connector [Windows]", "gatewayTimestamp": "2017-08-11T07:08:10.384830Z", "softwareVersion": "2.3.6.0", "uploaderID": "Gameboy13579"}, "message": {"StarPos": [-83.531, -114.813, -260.031], "StarType": "K", "AbsoluteMagnitude": 7.098755, "StarSystem": "Pleiades Sector QT-R c4-12", "SurfaceTemperature": 3856.0, "timestamp": "2017-08-11T07:08:43Z", "Age_MY": 12110, "OrbitalPeriod": 7582140416.0, "BodyName": "Pleiades Sector QT-R c4-12 A", "SemiMajorAxis": 1361966006272.0, "event": "Scan", "Radius": 549472128.0, "StellarMass": 0.597656, "Eccentricity": 0.050743, "DistanceFromArrivalLS": 0.0, "RotationPeriod": 269101.03125, "OrbitalInclination": 55.624729, "AxialTilt": 0.0, "Periapsis": 184.194183}}', 'schemaref': 'journal', 'message_search': 'null', 'schema_test': False, 'gatewaytimestamp': '2017-08-11T07:08:10.384830Z'}]

During handling of the above exception, another exception occurred:

Traceback (most recent call last):
  File "./eddnlistener.py", line 175, in <module>
    main()
  File "./eddnlistener.py", line 142, in main
    __db.insertMessage(__eddn_message.json, __eddn_message.schemaref, __eddn_message.gatewaytimestamp,__message_blacklisted, __message_valid, __message_schema_is_test)
  File "/mnt/tuesday/data0/edda/edda.git/eddn-listener/eddn/database/database.py", line 37, in insertMessage
    except sqlalchemy.exc.OperationalError as ex:
NameError: name 'sqlalchemy' is not defined
You have new mail in /home/users/athan/Maildir
athan@tuesday:/mnt/tuesday/data0/edda/edda.git/eddn-listener;
-=-=-=-=-=-=-=-=-=-=-=-=-=-=-=-=-=-=-=-=-=-=-=-=-=-=-=-=-=-=-=-=-=-=-=-=-=
